<?xml version="1.0" encoding="utf-8"?>
<robot
  name="astra_description">
  <link
    name="base_link">
    <inertial>
      <origin
        xyz="-0.1726 -0.0011902 0.37074"
        rpy="0 0 0" />
      <mass
        value="17.285" />
      <inertia
        ixx="0.88736"
        ixy="-9.7406E-10"
        ixz="-0.0042126"
        iyy="0.90938"
        iyz="1.6278E-09"
        izz="0.076259" />
    </inertial>
    <visual>
      <origin
        xyz="0 0 0"
        rpy="0 0 0" />
      <geometry>
        <mesh
          filename="package://astra_description/meshes/base_link.STL" />
      </geometry>
      <material
        name="">
        <color
          rgba="0.75294 0.75294 0.75294 1" />
      </material>
    </visual>
  </link>
  <link
    name="link_r1">
    <inertial>
      <origin
        xyz="0.027157 -3.0871E-12 -1.5958E-11"
        rpy="0 0 0" />
      <mass
        value="0.70739" />
      <inertia
        ixx="0.00060081"
        ixy="6.2989E-14"
        ixz="-1.3373E-13"
        iyy="0.00042262"
        iyz="1.4866E-09"
        izz="0.0002763" />
    </inertial>
    <visual>
      <origin
        xyz="0 0 0"
        rpy="0 0 0" />
      <geometry>
        <mesh
          filename="package://astra_description/meshes/link_r1.STL" />
      </geometry>
      <material
        name="">
        <color
          rgba="0.75294 0.75294 0.75294 1" />
      </material>
    </visual>
    <collision>
      <origin
        xyz="0 0 0"
        rpy="0 0 0" />
      <geometry>
        <mesh
          filename="package://astra_description/meshes/link_r1.STL" />
      </geometry>
    </collision>
  </link>
  <joint
    name="joint_r1"
    type="prismatic">
    <origin
      xyz="-0.0405 -0.065 0.227"
      rpy="0 0 -1.5708" />
    <parent
      link="base_link" />
    <child
      link="link_r1" />
    <axis
      xyz="0 0 1" />
    <limit
      lower="0"
      upper="1.2"
      effort="0"
      velocity="0" />
  </joint>
  
  <!-- SO-100 Right Arm Links -->
  
  <!-- SO-100 Right Base Link -->
  <link name="base_right">
    <inertial>
      <mass value="1.0"/>
      <origin xyz="0 0 0" rpy="0 0 0"/>
      <inertia ixx="0.01" ixy="0" ixz="0" iyy="0.01" iyz="0" izz="0.01"/>
    </inertial>
    <visual>
      <geometry>
        <mesh filename="package://astra_description/meshes/Base.STL"/>
      </geometry>
      <material name="3d_printed">
        <color rgba="1.0 0.82 0.12 1.0"/>
      </material>
    </visual>
    <visual>
      <geometry>
        <mesh filename="package://astra_description/meshes/Base_Motor.STL"/>
      </geometry>
      <material name="sts3215">
        <color rgba="0.1 0.1 0.1 1.0"/>
      </material>
    </visual>
  </link>
  
  <!-- Joint from link_r1 to base_right -->
  <joint name="joint_r1_to_base_right" type="fixed">
    <parent link="link_r1"/>
    <child link="base_right"/>
    <origin xyz="0.068 0 0" rpy="0 0 3.14159"/>
  </joint>
  
  <!-- SO-100 Right Arm Links -->
  <link name="link_r2">
    <inertial>
      <mass value="0.119226"/>
      <origin xyz="-9.07886e-05 0.0590972 0.031089" rpy="0 0 0"/>
      <inertia ixx="5.94278e-05" ixy="0" ixz="0" iyy="5.89975e-05" iyz="0" izz="3.13712e-05"/>
    </inertial>
    <visual>
      <geometry>
        <mesh filename="package://astra_description/meshes/Rotation_Pitch.STL"/>
      </geometry>
      <material name="3d_printed">
        <color rgba="1.0 0.82 0.12 1.0"/>
      </material>
    </visual>
    <visual>
      <geometry>
        <mesh filename="package://astra_description/meshes/Rotation_Pitch_Motor.STL"/>
      </geometry>
      <material name="sts3215">
        <color rgba="0.1 0.1 0.1 1.0"/>
      </material>
    </visual>
    <collision>
      <geometry>
        <mesh filename="package://astra_description/meshes/Rotation_Pitch.STL"/>
      </geometry>
    </collision>
  </link>

  <link name="link_r3">
    <inertial>
      <mass value="0.162409"/>
      <origin xyz="-1.72052e-05 0.0701802 0.00310545" rpy="0 0 0"/>
      <inertia ixx="0.000213312" ixy="0" ixz="0" iyy="0.000167164" iyz="0" izz="7.01522e-05"/>
    </inertial>
    <visual>
      <geometry>
        <mesh filename="package://astra_description/meshes/Upper_Arm.STL"/>
      </geometry>
      <material name="3d_printed"/>
    </visual>
    <visual>
      <geometry>
        <mesh filename="package://astra_description/meshes/Upper_Arm_Motor.STL"/>
      </geometry>
      <material name="sts3215"/>
    </visual>
    <collision>
      <geometry>
        <mesh filename="package://astra_description/meshes/Upper_Arm.STL"/>
      </geometry>
    </collision>
  </link>

  <link name="link_r4">
    <inertial>
      <mass value="0.147968"/>
      <origin xyz="-0.00339604 0.00137796 0.0768007" rpy="0 0 0"/>
      <inertia ixx="0.000138803" ixy="0" ixz="0" iyy="0.000107748" iyz="0" izz="4.84242e-05"/>
    </inertial>
    <visual>
      <geometry>
        <mesh filename="package://astra_description/meshes/Lower_Arm.STL"/>
      </geometry>
      <material name="3d_printed"/>
    </visual>
    <visual>
      <geometry>
        <mesh filename="package://astra_description/meshes/Lower_Arm_Motor.STL"/>
      </geometry>
      <material name="sts3215"/>
    </visual>
    <collision>
      <geometry>
        <mesh filename="package://astra_description/meshes/Lower_Arm.STL"/>
      </geometry>
    </collision>
  </link>

  <link name="link_r5">
    <inertial>
      <mass value="0.0661321"/>
      <origin xyz="-0.00852653 -0.0352279 -2.34622e-05" rpy="0 0 0"/>
      <inertia ixx="3.45403e-05" ixy="0" ixz="0" iyy="2.39041e-05" iyz="0" izz="1.94704e-05"/>
    </inertial>
    <visual>
      <geometry>
        <mesh filename="package://astra_description/meshes/Wrist_Pitch_Roll.STL"/>
      </geometry>
      <material name="3d_printed"/>
    </visual>
    <visual>
      <geometry>
        <mesh filename="package://astra_description/meshes/Wrist_Pitch_Roll_Motor.STL"/>
      </geometry>
      <material name="sts3215"/>
    </visual>
    <collision>
      <geometry>
        <mesh filename="package://astra_description/meshes/Wrist_Pitch_Roll.STL"/>
      </geometry>
    </collision>
  </link>

  <link name="link_r6">
    <inertial>
      <mass value="0.0929859"/>
      <origin xyz="0.00552377 -0.0280167 0.000483583" rpy="0 0 0"/>
      <inertia ixx="5.03136e-05" ixy="0" ixz="0" iyy="4.64098e-05" iyz="0" izz="2.72961e-05"/>
    </inertial>
    <visual>
      <geometry>
        <mesh filename="package://astra_description/meshes/Fixed_Jaw.STL"/>
      </geometry>
      <material name="3d_printed"/>
    </visual>
    <visual>
      <geometry>
        <mesh filename="package://astra_description/meshes/Fixed_Jaw_Motor.STL"/>
      </geometry>
      <material name="sts3215"/>
    </visual>
  </link>

  <!-- SO-100 Right Arm Joints -->
  <joint name="joint_r2" type="revolute">
    <parent link="base_right"/>
    <child link="link_r2"/>
    <origin xyz="0 -0.0452 0.0165" rpy="1.57079 0 0"/>
    <axis xyz="0 1 0"/>
    <limit lower="-1.57" upper="1.57" effort="35" velocity="1"/>
  </joint>

  <joint name="joint_r3" type="revolute">
    <parent link="link_r2"/>
    <child link="link_r3"/>
    <origin xyz="0 0.1025 0.0306" rpy="-1.8 0 0"/>
    <axis xyz="1 0 0"/>
    <limit lower="-1.57" upper="1.57" effort="35" velocity="1"/>
  </joint>

  <joint name="joint_r4" type="revolute">
    <parent link="link_r3"/>
    <child link="link_r4"/>
    <origin xyz="0 0.11257 0.028" rpy="1.57079 0 0"/>
    <axis xyz="1 0 0"/>
    <limit lower="-1.57" upper="1.57" effort="35" velocity="1"/>
  </joint>

  <joint name="joint_r5" type="revolute">
    <parent link="link_r4"/>
    <child link="link_r5"/>
    <origin xyz="0 0.0052 0.1349" rpy="-1 0 0"/>
    <axis xyz="1 0 0"/>
    <limit lower="-1.57" upper="1.57" effort="35" velocity="1"/>
  </joint>

  <joint name="joint_r6" type="revolute">
    <parent link="link_r5"/>
    <child link="link_r6"/>
    <origin xyz="0 -0.0601 0" rpy="0 1.57079 0"/>
    <axis xyz="0 1 0"/>
    <limit lower="-3.14158" upper="3.14158" effort="35" velocity="1"/>
  </joint>

  <!-- SO-100 Right Gripper -->
  <link name="link_r7r">
    <inertial>
      <mass value="0.0202444"/>
      <origin xyz="-0.00161745 -0.0303473 0.000449646" rpy="0 0 0"/>
      <inertia ixx="1.11265e-05" ixy="0" ixz="0" iyy="8.99651e-06" iyz="0" izz="2.99548e-06"/>
    </inertial>
    <visual>
      <geometry>
        <mesh filename="package://astra_description/meshes/Moving_Jaw.STL"/>
      </geometry>
      <material name="3d_printed"/>
    </visual>
  </link>

  <joint name="joint_r7r" type="revolute">
    <parent link="link_r6"/>
    <child link="link_r7r"/>
    <origin xyz="-0.0202 -0.0244 0" rpy="0 3.14158 0"/>
    <axis xyz="0 0 1"/>
    <limit lower="0" upper="1.57" effort="35" velocity="1"/>
  </joint>

  <link
    name="link_ree">
  </link>
  <joint
    name="joint_ree"
    type="fixed">
    <origin
      xyz="0.063 0 0.195"
      rpy="0 -1.5708 0" />
    <parent
      link="link_r6" />
    <child
      link="link_ree" />
  </joint>
  <link
    name="link_ree_teleop">
    <inertial>
      <origin xyz="0.0 0.0 0.0" rpy="0.0 0.0 0.0"/>
      <mass value="0.0"/>
      <inertia ixx="0.0" ixy="0.0" ixz="0.0" iyy="0.0" iyz="0.0" izz="0.0"/>
    </inertial>
    <collision>
      <geometry>
        <cylinder radius="0.0" length="0.0"/>
      </geometry>
      <origin xyz="0.0 0.0 0.0" rpy="0.0 0.0 0.0"/>
    </collision>
  </link>
  <joint
    name="joint_ree_teleop"
    type="fixed">
    <!-- eef on ball joint -->
    <!-- <origin
      xyz="0.0 0.0 0.0"
      rpy="0 -1.5708 0" /> -->
    <!-- eef on gripper center -->
    <!-- <origin
      xyz="0.080 0.0 0.200"
      rpy="0 -1.5708 0" /> -->
    <!-- eef on gripper center z-axis + 0.060m (consider teleop tag)  -->
    <origin
      xyz="0.020 0.0 0.200"
      rpy="0 -1.5708 0" />
    <parent
      link="link_r6" />
    <child
      link="link_ree_teleop" />
  </joint>
  <link
    name="link_l1">
    <inertial>
      <origin
        xyz="0.027157 -4.3066E-13 -6.6736E-12"
        rpy="0 0 0" />
      <mass
        value="0.70739" />
      <inertia
        ixx="0.00060081"
        ixy="-4.2708E-15"
        ixz="-1.6897E-15"
        iyy="0.00042262"
        iyz="1.4866E-09"
        izz="0.0002763" />
    </inertial>
    <visual>
      <origin
        xyz="0 0 0"
        rpy="0 0 0" />
      <geometry>
        <mesh
          filename="package://astra_description/meshes/link_l1.STL" />
      </geometry>
      <material
        name="">
        <color
          rgba="0.75294 0.75294 0.75294 1" />
      </material>
    </visual>
    <collision>
      <origin
        xyz="0 0 0"
        rpy="0 0 0" />
      <geometry>
        <mesh
          filename="package://astra_description/meshes/link_l1.STL" />
      </geometry>
    </collision>
  </link>
  <joint
    name="joint_l1"
    type="prismatic">
    <origin
      xyz="-0.0405 0.065 0.227"
      rpy="0 0 1.5708" />
    <parent
      link="base_link" />
    <child
      link="link_l1" />
    <axis
      xyz="0 0 1" />
    <limit
      lower="0"
      upper="1.2"
      effort="0"
      velocity="0" />
  </joint>
  
  <!-- SO-100 Left Arm Links -->
  
  <!-- SO-100 Left Base Link -->
  <link name="base_left">
    <inertial>
      <mass value="1.0"/>
      <origin xyz="0 0 0" rpy="0 0 0"/>
      <inertia ixx="0.01" ixy="0" ixz="0" iyy="0.01" iyz="0" izz="0.01"/>
    </inertial>
    <visual>
      <geometry>
        <mesh filename="package://astra_description/meshes/Base.STL"/>
      </geometry>
      <material name="3d_printed">
        <color rgba="1.0 0.82 0.12 1.0"/>
      </material>
    </visual>
    <visual>
      <geometry>
        <mesh filename="package://astra_description/meshes/Base_Motor.STL"/>
      </geometry>
      <material name="sts3215">
        <color rgba="0.1 0.1 0.1 1.0"/>
      </material>
    </visual>
  </link>
  
  <!-- Joint from link_l1 to base_left -->
  <joint name="joint_l1_to_base_left" type="fixed">
    <parent link="link_l1"/>
    <child link="base_left"/>
    <origin xyz="0.068 0 0" rpy="0 0 0"/>
  </joint>
  
  <!-- SO-100 Left Arm Links -->
  <link name="link_l2">
    <inertial>
      <mass value="0.119226"/>
      <origin xyz="-9.07886e-05 0.0590972 0.031089" rpy="0 0 0"/>
      <inertia ixx="5.94278e-05" ixy="0" ixz="0" iyy="5.89975e-05" iyz="0" izz="3.13712e-05"/>
    </inertial>
    <visual>
      <geometry>
        <mesh filename="package://astra_description/meshes/Rotation_Pitch.STL"/>
      </geometry>
      <material name="3d_printed">
        <color rgba="1.0 0.82 0.12 1.0"/>
      </material>
    </visual>
    <visual>
      <geometry>
        <mesh filename="package://astra_description/meshes/Rotation_Pitch_Motor.STL"/>
      </geometry>
      <material name="sts3215">
        <color rgba="0.1 0.1 0.1 1.0"/>
      </material>
    </visual>
    <collision>
      <geometry>
        <mesh filename="package://astra_description/meshes/Rotation_Pitch.STL"/>
      </geometry>
    </collision>
  </link>

  <link name="link_l3">
    <inertial>
      <mass value="0.162409"/>
      <origin xyz="-1.72052e-05 0.0701802 0.00310545" rpy="0 0 0"/>
      <inertia ixx="0.000213312" ixy="0" ixz="0" iyy="0.000167164" iyz="0" izz="7.01522e-05"/>
    </inertial>
    <visual>
      <geometry>
        <mesh filename="package://astra_description/meshes/Upper_Arm.STL"/>
      </geometry>
      <material name="3d_printed"/>
    </visual>
    <visual>
      <geometry>
        <mesh filename="package://astra_description/meshes/Upper_Arm_Motor.STL"/>
      </geometry>
      <material name="sts3215"/>
    </visual>
    <collision>
      <geometry>
        <mesh filename="package://astra_description/meshes/Upper_Arm.STL"/>
      </geometry>
    </collision>
  </link>

  <link name="link_l4">
    <inertial>
      <mass value="0.147968"/>
      <origin xyz="-0.00339604 0.00137796 0.0768007" rpy="0 0 0"/>
      <inertia ixx="0.000138803" ixy="0" ixz="0" iyy="0.000107748" iyz="0" izz="4.84242e-05"/>
    </inertial>
    <visual>
      <geometry>
        <mesh filename="package://astra_description/meshes/Lower_Arm.STL"/>
      </geometry>
      <material name="3d_printed"/>
    </visual>
    <visual>
      <geometry>
        <mesh filename="package://astra_description/meshes/Lower_Arm_Motor.STL"/>
      </geometry>
      <material name="sts3215"/>
    </visual>
    <collision>
      <geometry>
        <mesh filename="package://astra_description/meshes/Lower_Arm.STL"/>
      </geometry>
    </collision>
  </link>

  <link name="link_l5">
    <inertial>
      <mass value="0.0661321"/>
      <origin xyz="-0.00852653 -0.0352279 -2.34622e-05" rpy="0 0 0"/>
      <inertia ixx="3.45403e-05" ixy="0" ixz="0" iyy="2.39041e-05" iyz="0" izz="1.94704e-05"/>
    </inertial>
    <visual>
      <geometry>
        <mesh filename="package://astra_description/meshes/Wrist_Pitch_Roll.STL"/>
      </geometry>
      <material name="3d_printed"/>
    </visual>
    <visual>
      <geometry>
        <mesh filename="package://astra_description/meshes/Wrist_Pitch_Roll_Motor.STL"/>
      </geometry>
      <material name="sts3215"/>
    </visual>
    <collision>
      <geometry>
        <mesh filename="package://astra_description/meshes/Wrist_Pitch_Roll.STL"/>
      </geometry>
    </collision>
  </link>

  <link name="link_l6">
    <inertial>
      <mass value="0.0929859"/>
      <origin xyz="0.00552377 -0.0280167 0.000483583" rpy="0 0 0"/>
      <inertia ixx="5.03136e-05" ixy="0" ixz="0" iyy="4.64098e-05" iyz="0" izz="2.72961e-05"/>
    </inertial>
    <visual>
      <geometry>
        <mesh filename="package://astra_description/meshes/Fixed_Jaw.STL"/>
      </geometry>
      <material name="3d_printed"/>
    </visual>
    <visual>
      <geometry>
        <mesh filename="package://astra_description/meshes/Fixed_Jaw_Motor.STL"/>
      </geometry>
      <material name="sts3215"/>
    </visual>
  </link>

  <!-- SO-100 Left Arm Joints -->
  <joint name="joint_l2" type="revolute">
    <parent link="base_left"/>
    <child link="link_l2"/>
    <origin xyz="0 -0.0452 0.0165" rpy="1.57079 0 0"/>
    <axis xyz="0 1 0"/>
    <limit lower="-1.57" upper="1.57" effort="35" velocity="1"/>
  </joint>

  <joint name="joint_l3" type="revolute">
    <parent link="link_l2"/>
    <child link="link_l3"/>
    <origin xyz="0 0.1025 0.0306" rpy="-1.8 0 0"/>
    <axis xyz="1 0 0"/>
    <limit lower="-1.57" upper="1.57" effort="35" velocity="1"/>
  </joint>

  <joint name="joint_l4" type="revolute">
    <parent link="link_l3"/>
    <child link="link_l4"/>
    <origin xyz="0 0.11257 0.028" rpy="1.57079 0 0"/>
    <axis xyz="1 0 0"/>
    <limit lower="-1.57" upper="1.57" effort="35" velocity="1"/>
  </joint>

  <joint name="joint_l5" type="revolute">
    <parent link="link_l4"/>
    <child link="link_l5"/>
    <origin xyz="0 0.0052 0.1349" rpy="-1 0 0"/>
    <axis xyz="1 0 0"/>
    <limit lower="-1.57" upper="1.57" effort="35" velocity="1"/>
  </joint>

  <joint name="joint_l6" type="revolute">
    <parent link="link_l5"/>
    <child link="link_l6"/>
    <origin xyz="0 -0.0601 0" rpy="0 1.57079 0"/>
    <axis xyz="0 1 0"/>
    <limit lower="-3.14158" upper="3.14158" effort="35" velocity="1"/>
  </joint>

  <!-- SO-100 Left Gripper -->
  <link name="link_l7l">
    <inertial>
      <mass value="0.0202444"/>
      <origin xyz="-0.00161745 -0.0303473 0.000449646" rpy="0 0 0"/>
      <inertia ixx="1.11265e-05" ixy="0" ixz="0" iyy="8.99651e-06" iyz="0" izz="2.99548e-06"/>
    </inertial>
    <visual>
      <geometry>
        <mesh filename="package://astra_description/meshes/Moving_Jaw.STL"/>
      </geometry>
      <material name="3d_printed"/>
    </visual>
  </link>

  <joint name="joint_l7l" type="revolute">
    <parent link="link_l6"/>
    <child link="link_l7l"/>
    <origin xyz="-0.0202 -0.0244 0" rpy="0 3.14158 0"/>
    <axis xyz="0 0 1"/>
    <limit lower="0" upper="1.57" effort="35" velocity="1"/>
  </joint>

  <link
    name="link_lee">
  </link>
  <joint
    name="joint_lee"
    type="fixed">
    <origin
      xyz="0.063 0 0.195"
      rpy="0 -1.5708 0" />
    <parent
      link="link_l6" />
    <child
      link="link_lee" />
    <axis
      xyz="0 0 0" />
  </joint>
  <link
    name="link_lee_teleop">
    <inertial>
      <origin xyz="0.0 0.0 0.0" rpy="0.0 0.0 0.0"/>
      <mass value="0.0"/>
      <inertia ixx="0.0" ixy="0.0" ixz="0.0" iyy="0.0" iyz="0.0" izz="0.0"/>
    </inertial>
    <collision>
      <geometry>
        <cylinder radius="0.0" length="0.0"/>
      </geometry>
      <origin xyz="0.0 0.0 0.0" rpy="0.0 0.0 0.0"/>
    </collision>
  </link>
  <joint
    name="joint_lee_teleop"
    type="fixed">
    <!-- eef on ball joint -->
    <!-- <origin
      xyz="0.0 0.0 0.0"
      rpy="0 -1.5708 0" /> -->
    <!-- eef on gripper center -->
    <!-- <origin
      xyz="0.080 0.0 0.200"
      rpy="0 -1.5708 0" /> -->
    <!-- eef on gripper center z-axis + 0.060m (consider teleop tag)  -->
    <origin
      xyz="0.020 0.0 0.200"
      rpy="0 -1.5708 0" />
    <parent
      link="link_l6" />
    <child
      link="link_lee_teleop" />
    <axis
      xyz="0 0 0" />
  </joint>
  <link
    name="link_head_pan">
    <inertial>
      <origin
        xyz="7.4339E-05 0.033099 -0.027091"
        rpy="0 0 0" />
      <mass
        value="0.087098" />
      <inertia
        ixx="3.1196E-05"
        ixy="3.7815E-10"
        ixz="-1.0586E-09"
        iyy="2.6879E-05"
        iyz="-5.5018E-06"
        izz="1.8673E-05" />
    </inertial>
    <visual>
      <origin
        xyz="0 0 0"
        rpy="0 0 0" />
      <geometry>
        <mesh
          filename="package://astra_description/meshes/link_head_pan.STL" />
      </geometry>
      <material
        name="">
        <color
          rgba="0.75294 0.75294 0.75294 1" />
      </material>
    </visual>
  </link>
  <joint
    name="joint_head_pan"
    type="revolute">
    <origin
      xyz="0.05 0 1.429"
      rpy="-3.1416 0 0" />
    <parent
      link="base_link" />
    <child
      link="link_head_pan" />
    <axis
      xyz="0 0 1" />
    <limit
      lower="-1.57"
      upper="1.57"
      effort="0"
      velocity="0" />
  </joint>
  <link
    name="link_head_tilt">
    <inertial>
      <origin
        xyz="-0.0076351 5.9952E-15 -0.0029726"
        rpy="0 0 0" />
      <mass
        value="0.032288" />
      <inertia
        ixx="5.5219E-06"
        ixy="1.4324E-20"
        ixz="5.4317E-08"
        iyy="4.6642E-06"
        iyz="-1.2451E-21"
        izz="5.6225E-06" />
    </inertial>
    <visual>
      <origin
        xyz="0 0 0"
        rpy="0 0 0" />
      <geometry>
        <mesh
          filename="package://astra_description/meshes/link_head_tilt.STL" />
      </geometry>
      <material
        name="">
        <color
          rgba="0.75294 0.75294 0.75294 1" />
      </material>
    </visual>
  </link>
  <joint
    name="joint_head_tilt"
    type="revolute">
    <origin
      xyz="0 0 0"
      rpy="1.5708 0 0" />
    <parent
      link="link_head_pan" />
    <child
      link="link_head_tilt" />
    <axis
      xyz="0 0 1" />
    <limit
      lower="-3.14"
      upper="3.14"
      effort="0"
      velocity="0" />
  </joint>
</robot>